Workbook

Sheet Checklist
A1: GCSE curriculum coverage checklist
A2: Choose ☐ or ☑ in the Complete column. Filter by subject, level, paper or tier to plan revision.
A3: Complete | B3: Subject | C3: Level 1 | D3: Level 2 | E3: Level 3 | F3: Description | G3: Component / paper | H3: Tier | I3: Applicability | J3: Source
A4: ☐ | B4: Business | C4: Theme 1: Investigating small business | D4: 1.1 Enterprise and entrepreneurship | E4: Added value and the role and characteristics of entrepreneurs | G4: Paper 1 | H4: All tiers | I4: Common | J4: Open source
A5: ☐ | B5: Business | C5: Theme 1: Investigating small business | D5: 1.1 Enterprise and entrepreneurship | E5: Customer needs | G5: Paper 1 | H5: All tiers | I5: Common | J5: Open source
A6: ☐ | B6: Business | C6: Theme 1: Investigating small business | D6: 1.1 Enterprise and entrepreneurship | E6: Dynamic business ideas and obsolescence | G6: Paper 1 | H6: All tiers | I6: Common | J6: Open source
A7: ☐ | B7: Business | C7: Theme 1: Investigating small business | D7: 1.1 Enterprise and entrepreneurship | E7: Enterprise | G7: Paper 1 | H7: All tiers | I7: Common | J7: Open source
A8: ☐ | B8: Business | C8: Theme 1: Investigating small business | D8: 1.1 Enterprise and entrepreneurship | E8: Risk and reward | G8: Paper 1 | H8: All tiers | I8: Common | J8: Open source
A9: ☐ | B9: Business | C9: Theme 1: Investigating small business | D9: 1.2 Spotting a business opportunity | E9: Customer needs | G9: Paper 1 | H9: All tiers | I9: Common | J9: Open source
A10: ☐ | B10: Business | C10: Theme 1: Investigating small business | D10: 1.2 Spotting a business opportunity | E10: Market mapping and competition | G10: Paper 1 | H10: All tiers | I10: Common | J10: Open source
A11: ☐ | B11: Business | C11: Theme 1: Investigating small business | D11: 1.2 Spotting a business opportunity | E11: Primary and secondary market research | G11: Paper 1 | H11: All tiers | I11: Common | J11: Open source
A12: ☐ | B12: Business | C12: Theme 1: Investigating small business | D12: 1.2 Spotting a business opportunity | E12: Qualitative and quantitative data and reliability | G12: Paper 1 | H12: All tiers | I12: Common | J12: Open source
A13: ☐ | B13: Business | C13: Theme 1: Investigating small business | D13: 1.2 Spotting a business opportunity | E13: Segmentation | G13: Paper 1 | H13: All tiers | I13: Common | J13: Open source
A14: ☐ | B14: Business | C14: Theme 1: Investigating small business | D14: 1.3 Putting a business idea into practice | E14: Appropriate sources of finance | G14: Paper 1 | H14: All tiers | I14: Common | J14: Open source
A15: ☐ | B15: Business | C15: Theme 1: Investigating small business | D15: 1.3 Putting a business idea into practice | E15: Break-even and margin of safety | G15: Paper 1 | H15: All tiers | I15: Common | J15: Open source
... A62: ☐ | B62: Business | C62: Theme 2: Building a business | D62: 2.5 Making human resource decisions | E62: Recruitment and training | G62: Paper 2 | H62: All tiers | I62: Common | J62: Open source
A63: ☐ | B63: Combined Science | C63: Atomic structure | D63: Atomic models | G63: Physics Paper 1 | H63: All tiers | I63: Common | J63: Open source
A64: ☐ | B64: Combined Science | C64: Atomic structure | D64: Half-life and contamination | G64: Physics Paper 1 | H64: All tiers | I64: Common | J64: Open source
A65: ☐ | B65: Combined Science | C65: Atomic structure | D65: Isotopes and nuclear radiation | G65: Physics Paper 1 | H65: All tiers | I65: Common | J65: Open source
A66: ☐ | B66: Combined Science | C66: Atomic structure | D66: Uses and hazards of radiation | G66: Physics Paper 1 | H66: All tiers | I66: Common | J66: Open source
A67: ☐ | B67: Combined Science | C67: Atomic structure and the periodic table | D67: 1 and 7 | G67: Chemistry Paper 1 | H67: All tiers | I67: Common | J67: Open source
A68: ☐ | B68: Combined Science | C68: Atomic structure and the periodic table | D68: Atomic models and electronic structure | G68: Chemistry Paper 1 | H68: All tiers | I68: Common | J68: Open source
A69: ☐ | B69: Combined Science | C69: Atomic structure and the periodic table | D69: Atoms | G69: Chemistry Paper 1 | H69: All tiers | I69: Common | J69: Open source
A70: ☐ | B70: Combined Science | C70: Atomic structure and the periodic table | D70: Elements | G70: Chemistry Paper 1 | H70: All tiers | I70: Common | J70: Open source
A71: ☐ | B71: Combined Science | C71: Atomic structure and the periodic table | D71: Groups 0 | G71: Chemistry Paper 1 | H71: All tiers | I71: Common | J71: Open source
A72: ☐ | B72: Combined Science | C72: Atomic structure and the periodic table | D72: Mixtures and equations | G72: Chemistry Paper 1 | H72: All tiers | I72: Common | J72: Open source
A73: ☐ | B73: Combined Science | C73: Atomic structure and the periodic table | D73: Periodic table development | G73: Chemistry Paper 1 | H73: All tiers | I73: Common | J73: Open source
A74: ☐ | B74: Combined Science | C74: Atomic structure and the periodic table | D74: Transition metals | G74: Chemistry Paper 1 | H74: All tiers | I74: Common | J74: Open source
... A204: ☐ | B204: Combined Science | C204: Waves | D204: Wave properties and equations | G204: Physics Paper 2 | H204: All tiers | I204: Common | J204: Open source
A205: ☐ | B205: Design and Technology | C205: Core technical principles | D205: Developments in new materials | E205: Composite and technical textiles | G205: Paper 1 Section A | H205: All tiers | I205: Common | J205: Open source
A206: ☐ | B206: Design and Technology | C206: Core technical principles | D206: Developments in new materials | E206: Cost and sustainability | G206: Paper 1 Section A | H206: All tiers | I206: Common | J206: Open source
A207: ☐ | B207: Design and Technology | C207: Core technical principles | D207: Developments in new materials | E207: Evaluating functional benefit | G207: Paper 1 Section A | H207: All tiers | I207: Common | J207: Open source
A208: ☐ | B208: Design and Technology | C208: Core technical principles | D208: Developments in new materials | E208: Modern | G208: Paper 1 Section A | H208: All tiers | I208: Common | J208: Open source
A209: ☐ | B209: Design and Technology | C209: Core technical principles | D209: Developments in new materials | E209: Properties and applications | G209: Paper 1 Section A | H209: All tiers | I209: Common | J209: Open source
A210: ☐ | B210: Design and Technology | C210: Core technical principles | D210: Developments in new materials | E210: Smart | G210: Paper 1 Section A | H210: All tiers | I210: Common | J210: Open source
A211: ☐ | B211: Design and Technology | C211: Core technical principles | D211: Energy generation and storage | E211: Arguments for and against sources | G211: Paper 1 Section A | H211: All tiers | I211: Common | J211: Open source
A212: ☐ | B212: Design and Technology | C212: Core technical principles | D212: Energy generation and storage | E212: Batteries | G212: Paper 1 Section A | H212: All tiers | I212: Common | J212: Open source
A213: ☐ | B213: Design and Technology | C213: Core technical principles | D213: Energy generation and storage | E213: Fossil fuels | G213: Paper 1 Section A | H213: All tiers | I213: Common | J213: Open source
A214: ☐ | B214: Design and Technology | C214: Core technical principles | D214: Energy generation and storage | E214: Kinetic storage and energy-system selection | G214: Paper 1 Section A | H214: All tiers | I214: Common | J214: Open source
A215: ☐ | B215: Design and Technology | C215: Core technical principles | D215: Energy generation and storage | E215: Nuclear and renewable generation | G215: Paper 1 Section A | H215: All tiers | I215: Common | J215: Open source
...

Sheet Summary
A1: Curriculum coverage by subject
A2: Subject | B2: Exam board | C2: Specification | D2: Detailed topics | E2: Covered | F2: Remaining | G2: Completion
A3: Business | B3: Edexcel | C3: 1BS0 | D3: 59 | E3: =COUNTIFS(Checklist!$B$4:$B$713,A3,Checklist!$A$4:$A$713,"☑") -> 0 | F3: =D3-E3 -> 59 | G3: =IFERROR(E3/D3,0) -> 0
A4: Combined Science | B4: AQA | C4: 8464 | D4: 142 | E4: =COUNTIFS(Checklist!$B$4:$B$713,A4,Checklist!$A$4:$A$713,"☑") -> 0 | F4: =D4-E4 -> 142 | G4: =IFERROR(E4/D4,0) -> 0
A5: Design and Technology | B5: AQA | C5: 8552 | D5: 107 | E5: =COUNTIFS(Checklist!$B$4:$B$713,A5,Checklist!$A$4:$A$713,"☑") -> 0 | F5: =D5-E5 -> 107 | G5: =IFERROR(E5/D5,0) -> 0
A6: English Language | B6: AQA | C6: 8700 | D6: 17 | E6: =COUNTIFS(Checklist!$B$4:$B$713,A6,Checklist!$A$4:$A$713,"☑") -> 0 | F6: =D6-E6 -> 17 | G6: =IFERROR(E6/D6,0) -> 0
A7: English Literature | B7: AQA | C7: 8702 | D7: 109 | E7: =COUNTIFS(Checklist!$B$4:$B$713,A7,Checklist!$A$4:$A$713,"☑") -> 0 | F7: =D7-E7 -> 109 | G7: =IFERROR(E7/D7,0) -> 0
A8: Geography | B8: AQA | C8: 8035 | D8: 112 | E8: =COUNTIFS(Checklist!$B$4:$B$713,A8,Checklist!$A$4:$A$713,"☑") -> 0 | F8: =D8-E8 -> 112 | G8: =IFERROR(E8/D8,0) -> 0
A9: History | B9: Edexcel | C9: 1HI0 | D9: 57 | E9: =COUNTIFS(Checklist!$B$4:$B$713,A9,Checklist!$A$4:$A$713,"☑") -> 0 | F9: =D9-E9 -> 57 | G9: =IFERROR(E9/D9,0) -> 0
A10: Mathematics | B10: AQA | C10: 8300 | D10: 107 | E10: =COUNTIFS(Checklist!$B$4:$B$713,A10,Checklist!$A$4:$A$713,"☑") -> 0 | F10: =D10-E10 -> 107 | G10: =IFERROR(E10/D10,0) -> 0
A12: All subjects | D12: =SUM(D3:D10) -> 710 | E12: =SUM(E3:E10) -> 0 | F12: =SUM(F3:F10) -> 710 | G12: =IFERROR(E12/D12,0) -> 0
